[2024-01-11T10:11:05.634+0000] {taskinstance.py:1957} INFO - Dependencies all met for dep_context=non-requeueable deps ti=<TaskInstance: api_dag.save_posts manual__2024-01-11T10:11:02.902208+00:00 [queued]>
[2024-01-11T10:11:05.644+0000] {taskinstance.py:1957} INFO - Dependencies all met for dep_context=requeueable deps ti=<TaskInstance: api_dag.save_posts manual__2024-01-11T10:11:02.902208+00:00 [queued]>
[2024-01-11T10:11:05.644+0000] {taskinstance.py:2171} INFO - Starting attempt 1 of 1
[2024-01-11T10:11:05.660+0000] {taskinstance.py:2192} INFO - Executing <Task(PythonOperator): save_posts> on 2024-01-11 10:11:02.902208+00:00
[2024-01-11T10:11:05.667+0000] {standard_task_runner.py:60} INFO - Started process 40145 to run task
[2024-01-11T10:11:05.671+0000] {standard_task_runner.py:87} INFO - Running: ['***', 'tasks', 'run', 'api_dag', 'save_posts', 'manual__2024-01-11T10:11:02.902208+00:00', '--job-id', '9598', '--raw', '--subdir', 'DAGS_FOLDER/api_dag.py', '--cfg-path', '/tmp/tmp10q6kkvh']
[2024-01-11T10:11:05.674+0000] {standard_task_runner.py:88} INFO - Job 9598: Subtask save_posts
[2024-01-11T10:11:05.726+0000] {task_command.py:423} INFO - Running <TaskInstance: api_dag.save_posts manual__2024-01-11T10:11:02.902208+00:00 [running]> on host d3b0837e9e03
[2024-01-11T10:11:05.829+0000] {taskinstance.py:2481} INFO - Exporting env vars: AIRFLOW_CTX_DAG_OWNER='***' AIRFLOW_CTX_DAG_ID='api_dag' AIRFLOW_CTX_TASK_ID='save_posts' AIRFLOW_CTX_EXECUTION_DATE='2024-01-11T10:11:02.902208+00:00' AIRFLOW_CTX_TRY_NUMBER='1' AIRFLOW_CTX_DAG_RUN_ID='manual__2024-01-11T10:11:02.902208+00:00'
[2024-01-11T10:11:05.833+0000] {taskinstance.py:2699} ERROR - Task failed with exception
Traceback (most recent call last):
  File "/home/airflow/.local/lib/python3.8/site-packages/airflow/models/taskinstance.py", line 433, in _execute_task
    result = execute_callable(context=context, **execute_callable_kwargs)
  File "/home/airflow/.local/lib/python3.8/site-packages/airflow/operators/python.py", line 199, in execute
    return_value = self.execute_callable()
  File "/home/airflow/.local/lib/python3.8/site-packages/airflow/operators/python.py", line 216, in execute_callable
    return self.python_callable(*self.op_args, **self.op_kwargs)
  File "/opt/airflow/dags/api_dag.py", line 11, in save_posts
    with open('/Users/khenshin_arif/airflow/data/posts.json', 'w') as f:
FileNotFoundError: [Errno 2] No such file or directory: '/Users/khenshin_arif/airflow/data/posts.json'
[2024-01-11T10:11:05.842+0000] {taskinstance.py:1138} INFO - Marking task as FAILED. dag_id=api_dag, task_id=save_posts, execution_date=20240111T101102, start_date=20240111T101105, end_date=20240111T101105
[2024-01-11T10:11:05.856+0000] {standard_task_runner.py:107} ERROR - Failed to execute job 9598 for task save_posts ([Errno 2] No such file or directory: '/Users/khenshin_arif/airflow/data/posts.json'; 40145)
[2024-01-11T10:11:05.882+0000] {local_task_job_runner.py:234} INFO - Task exited with return code 1
[2024-01-11T10:11:05.897+0000] {taskinstance.py:3281} INFO - 0 downstream tasks scheduled from follow-on schedule check
