[2024-01-11T10:11:35.463+0000] {taskinstance.py:1957} INFO - Dependencies all met for dep_context=non-requeueable deps ti=<TaskInstance: api_dag.save_posts manual__2024-01-11T10:11:33.666030+00:00 [queued]>
[2024-01-11T10:11:35.476+0000] {taskinstance.py:1957} INFO - Dependencies all met for dep_context=requeueable deps ti=<TaskInstance: api_dag.save_posts manual__2024-01-11T10:11:33.666030+00:00 [queued]>
[2024-01-11T10:11:35.476+0000] {taskinstance.py:2171} INFO - Starting attempt 1 of 1
[2024-01-11T10:11:35.493+0000] {taskinstance.py:2192} INFO - Executing <Task(PythonOperator): save_posts> on 2024-01-11 10:11:33.666030+00:00
[2024-01-11T10:11:35.502+0000] {standard_task_runner.py:60} INFO - Started process 40160 to run task
[2024-01-11T10:11:35.505+0000] {standard_task_runner.py:87} INFO - Running: ['***', 'tasks', 'run', 'api_dag', 'save_posts', 'manual__2024-01-11T10:11:33.666030+00:00', '--job-id', '9599', '--raw', '--subdir', 'DAGS_FOLDER/api_dag.py', '--cfg-path', '/tmp/tmpfflmvq7v']
[2024-01-11T10:11:35.508+0000] {standard_task_runner.py:88} INFO - Job 9599: Subtask save_posts
[2024-01-11T10:11:35.570+0000] {task_command.py:423} INFO - Running <TaskInstance: api_dag.save_posts manual__2024-01-11T10:11:33.666030+00:00 [running]> on host d3b0837e9e03
[2024-01-11T10:11:35.664+0000] {taskinstance.py:2481} INFO - Exporting env vars: AIRFLOW_CTX_DAG_OWNER='***' AIRFLOW_CTX_DAG_ID='api_dag' AIRFLOW_CTX_TASK_ID='save_posts' AIRFLOW_CTX_EXECUTION_DATE='2024-01-11T10:11:33.666030+00:00' AIRFLOW_CTX_TRY_NUMBER='1' AIRFLOW_CTX_DAG_RUN_ID='manual__2024-01-11T10:11:33.666030+00:00'
[2024-01-11T10:11:35.670+0000] {taskinstance.py:2699} ERROR - Task failed with exception
Traceback (most recent call last):
  File "/home/airflow/.local/lib/python3.8/site-packages/airflow/models/taskinstance.py", line 433, in _execute_task
    result = execute_callable(context=context, **execute_callable_kwargs)
  File "/home/airflow/.local/lib/python3.8/site-packages/airflow/operators/python.py", line 199, in execute
    return_value = self.execute_callable()
  File "/home/airflow/.local/lib/python3.8/site-packages/airflow/operators/python.py", line 216, in execute_callable
    return self.python_callable(*self.op_args, **self.op_kwargs)
  File "/opt/airflow/dags/api_dag.py", line 11, in save_posts
    with open('/Users/khenshin_arif/airflow/data/posts.json', 'w') as f:
FileNotFoundError: [Errno 2] No such file or directory: '/Users/khenshin_arif/airflow/data/posts.json'
[2024-01-11T10:11:35.681+0000] {taskinstance.py:1138} INFO - Marking task as FAILED. dag_id=api_dag, task_id=save_posts, execution_date=20240111T101133, start_date=20240111T101135, end_date=20240111T101135
[2024-01-11T10:11:35.692+0000] {standard_task_runner.py:107} ERROR - Failed to execute job 9599 for task save_posts ([Errno 2] No such file or directory: '/Users/khenshin_arif/airflow/data/posts.json'; 40160)
[2024-01-11T10:11:35.717+0000] {local_task_job_runner.py:234} INFO - Task exited with return code 1
[2024-01-11T10:11:35.733+0000] {taskinstance.py:3281} INFO - 0 downstream tasks scheduled from follow-on schedule check
