[2024-01-09T12:51:42.267+0000] {taskinstance.py:1957} INFO - Dependencies all met for dep_context=non-requeueable deps ti=<TaskInstance: dag_with_taskflow_api_v02.get_name manual__2024-01-09T12:49:38.785026+00:00 [queued]>
[2024-01-09T12:51:42.276+0000] {taskinstance.py:1957} INFO - Dependencies all met for dep_context=requeueable deps ti=<TaskInstance: dag_with_taskflow_api_v02.get_name manual__2024-01-09T12:49:38.785026+00:00 [queued]>
[2024-01-09T12:51:42.277+0000] {taskinstance.py:2171} INFO - Starting attempt 2 of 6
[2024-01-09T12:51:42.291+0000] {taskinstance.py:2192} INFO - Executing <Task(_PythonDecoratedOperator): get_name> on 2024-01-09 12:49:38.785026+00:00
[2024-01-09T12:51:42.298+0000] {standard_task_runner.py:60} INFO - Started process 5600 to run task
[2024-01-09T12:51:42.301+0000] {standard_task_runner.py:87} INFO - Running: ['***', 'tasks', 'run', 'dag_with_taskflow_api_v02', 'get_name', 'manual__2024-01-09T12:49:38.785026+00:00', '--job-id', '52', '--raw', '--subdir', 'DAGS_FOLDER/dag_with_taskflow_api.py', '--cfg-path', '/tmp/tmpjopcd4t5']
[2024-01-09T12:51:42.306+0000] {standard_task_runner.py:88} INFO - Job 52: Subtask get_name
[2024-01-09T12:51:42.353+0000] {task_command.py:423} INFO - Running <TaskInstance: dag_with_taskflow_api_v02.get_name manual__2024-01-09T12:49:38.785026+00:00 [running]> on host d3b0837e9e03
[2024-01-09T12:51:42.433+0000] {taskinstance.py:2481} INFO - Exporting env vars: AIRFLOW_CTX_DAG_OWNER='arif' AIRFLOW_CTX_DAG_ID='dag_with_taskflow_api_v02' AIRFLOW_CTX_TASK_ID='get_name' AIRFLOW_CTX_EXECUTION_DATE='2024-01-09T12:49:38.785026+00:00' AIRFLOW_CTX_TRY_NUMBER='2' AIRFLOW_CTX_DAG_RUN_ID='manual__2024-01-09T12:49:38.785026+00:00'
[2024-01-09T12:51:42.436+0000] {taskinstance.py:2699} ERROR - Task failed with exception
Traceback (most recent call last):
  File "/home/airflow/.local/lib/python3.8/site-packages/airflow/models/taskinstance.py", line 433, in _execute_task
    result = execute_callable(context=context, **execute_callable_kwargs)
  File "/home/airflow/.local/lib/python3.8/site-packages/airflow/decorators/base.py", line 242, in execute
    return_value = super().execute(context)
  File "/home/airflow/.local/lib/python3.8/site-packages/airflow/operators/python.py", line 199, in execute
    return_value = self.execute_callable()
  File "/home/airflow/.local/lib/python3.8/site-packages/airflow/operators/python.py", line 216, in execute_callable
    return self.python_callable(*self.op_args, **self.op_kwargs)
  File "/opt/airflow/dags/dag_with_taskflow_api.py", line 26, in get_name
    first_name: 'Fahim',
NameError: name 'first_name' is not defined
[2024-01-09T12:51:42.444+0000] {taskinstance.py:1138} INFO - Marking task as UP_FOR_RETRY. dag_id=dag_with_taskflow_api_v02, task_id=get_name, execution_date=20240109T124938, start_date=20240109T125142, end_date=20240109T125142
[2024-01-09T12:51:42.461+0000] {standard_task_runner.py:107} ERROR - Failed to execute job 52 for task get_name (name 'first_name' is not defined; 5600)
[2024-01-09T12:51:42.513+0000] {local_task_job_runner.py:234} INFO - Task exited with return code 1
[2024-01-09T12:51:42.542+0000] {taskinstance.py:3281} INFO - 0 downstream tasks scheduled from follow-on schedule check
